<mujoco>
    <option gravity="0 0 -9.80" timestep="0.002"/>
    <size nstack="5000"/>
    
    <asset>
        <texture type="skybox" builtin="gradient" rgb1=".3 .5 .7" rgb2="0 0 0" width="32" height="512"/>
        <texture name="grid" type="2d" builtin="checker" width="512" height="512" rgb1=".1 .2 .3" rgb2=".2 .3 .4"/>
        <texture name='highlight' type='2d' builtin='gradient' rgb1='255 255 255' rgb2='255 255 255' width='512' height='512'/>
        <material name='ball' texture='highlight' texrepeat='1 1' texuniform='true'/>
        <material name="grid" texture="grid" texrepeat="1 1" texuniform="true" reflectance=".0"/>
    </asset>

    <worldbody>
        <geom name="floor" size="10 10 .05" type="plane" material="grid" friction="3.0 1.5 0.5"/>
        <light name="spotlight" mode="targetbodycom" target="bb8" diffuse=".8 .8 .8" specular="0.3 0.3 0.3" pos="0 -6 4" cutoff="30"/>
        <light name="top" pos="0 0 2" mode="trackcom"/>

        <body name='bb8' pos="0 0 1">
            <joint name='bb8_free' type="free"/>
            <geom name="bb8" type="sphere" size=".1" rgba="1 0.6 0 1" mass="2.0"/>
            
            <body name="head" pos="0 0 0.16">
                <joint name="head_joint"/>
                <geom name="head_geom" type="box" size=".06 .06 .06" rgba="1 1 1 1" mass="0.3"/>
            </body>
        </body>
    </worldbody>
</mujoco>