<mujoco model="bb8_car">
    <compiler angle="radian" />
    <option timestep="0.001" integrator="implicit">
        <flag warmstart="enable" />
    </option>

    <asset>
        <mesh name="base_link" content_type="model/stl" file="base_link.STL" scale="1.3 1.3 1.3" />
        <mesh name="a1" content_type="model/stl" file="a1.STL" />
        <mesh name="a2" content_type="model/stl" file="a2.STL" />
        <mesh name="h" content_type="model/stl" file="h.STL" scale="1.275 1.275 1.275" />
        <mesh name="w1" content_type="model/stl" file="w1.STL" scale="1.125 1.125 1.125" />
        <mesh name="w2" content_type="model/stl" file="w2.STL" scale="1.125 1.125 1.125" />
        <mesh name="w3" content_type="model/stl" file="w3.STL" scale="1.125 1.125 1.125" />
        <mesh name="w4" content_type="model/stl" file="w4.STL" scale="1.125 1.125 1.125" />
        <texture name="grid" type="2d" builtin="checker" rgb1=".1 .2 .3" rgb2=".2 .3 .4" width="300"
            height="300" />
        <material name="grid" texture="grid" texrepeat="8 8" reflectance=".2" />
    </asset>

    <worldbody>
        <light name="top" pos="0 0 20" />
        <geom name="floor" type="plane" pos="0 0 0" size="10 10 0.1" material="grid"
            friction="1.0 0.005 0.0001" contype="1"
            conaffinity="1" />
        <body name="base_link" pos="0 0 0.6" quat="-0.707107 0.707107 0 0">
            <!-- <freejoint /> -->

            <!-- <joint name="base_link_x" type="slide" axis="1 0 0" damping="0.1" />
      <joint name="base_link_z" type="slide" axis="0 0 1" damping="0.1" /> -->

            <freejoint name="base_link_freejoint" />

            <camera name="track_com" pos="1.253 -1.502 0.378"
                xyaxes="0.768 0.641 0.000 -0.101 0.122 0.987" mode="trackcom" />
            <!-- <inertial pos="-4.4409E-16 0.027063 -3.3307E-16" quat="0 0 0 1" mass="2.4283"
        diaginertia="0.0059267 0.0098916 0.0059267" /> -->
            <inertial pos="-4.4409E-16 0.027063 -3.3307E-16" quat="0 0 0 1" mass="20"
                diaginertia="0.0059267 0.0098916 0.0059267" />

            <geom type="mesh" rgba="0.79216 0.81961 0.93333 1" mesh="base_link" />
            <geom name="sphere" type="sphere" pos="0 -0.05625 0" size="0.26"
                rgba="0.988 0.612 0.263 0.25"
                contype="0" conaffinity="0" />
            <!-- <body name="sphere" pos="0 0 0.1">
        <inertial pos="0 0 0" mass="0" diaginertia="0.002 0.002 0.002" />
        <geom type="sphere" size="0.1" rgba="0.1 0.1 0.8 1" />
      </body> -->
            <body name="a1" pos="0 -0.02 0" quat="0.356335 0.356338 0.610757 -0.610757">
                <inertial pos="0 0 0.033964" quat="0.707107 0 0 0.707107" mass="0.027142"
                    diaginertia="5.8419e-06 5.8158e-06 1.7833e-06" />
                <joint name="a1" pos="0 0 0" axis="0 0 -1" />
                <geom type="mesh" rgba="0.79216 0.81961 0.93333 1" mesh="a1" />
                <body name="a2" pos="0 0 0.06" quat="-3.1459e-06 1.89624e-06 0.516236 -0.856446">
                    <inertial pos="4.0307e-08 1.6883e-08 0.12424" quat="0.999977 0 0 0.0067613"
                        mass="0.072732" diaginertia="0.00032679 0.00032678 3.6454e-06" />
                    <joint name="a2" pos="0 0 0" axis="1 0 0" />
                    <geom type="mesh" rgba="0.79216 0.81961 0.93333 1" mesh="a2" friction="1 1 1"
                        condim="6" />
                    <body name="h" pos="0 0 0.34" quat="0.51312 0.486525 0.513122 -0.486527">
                        <inertial pos="0.0625 0 0" mass="0.5"
                            diaginertia="0.0083776 0.0054323 0.0054323" />
                        <joint name="h" pos="0 0 0" axis="-1 0 0" />
                        <geom type="mesh" rgba="0.79216 0.81961 0.93333 1" mesh="h" />
                    </body>
                </body>
            </body>
            <!-- <body name="w1" pos="-0.125 0.117 0" quat="0.499998 0.5 -0.5 0.500002"> -->
            <body name="w1" pos="-0.1 0.117 0.095" quat="0.683 0.183 0.183 0.683">
                <inertial pos="0 -0.01 0" quat="0.707107 0 0 0.707107" mass="0.15708"
                    diaginertia="0.00019635 0.00010341 0.00010341" />
                <joint name="w1" pos="0 0 0" axis="0 1 0" damping="0.1" />
                <geom type="mesh" mesh="w1" friction="0.2 0.005 0.01" condim="6" />
            </body>
            <!-- <body name="w2" pos="0 0.117 -0.125" quat="0.499998 0.5 -0.5 0.500002"> -->
            <body name="w2" pos="0 0.117 -0.125" quat="0.499998 0.5 -0.5 0.500002">
                <inertial pos="0.01 0 0" mass="0.15708"
                    diaginertia="0.00019635 0.00010341 0.00010341" />
                <joint name="w2" pos="0 0 0" axis="-1 0 0" damping="0.1" />
                <geom type="mesh" mesh="w2" friction="0.2 0.005 0.01" condim="6" />
            </body>
            <!-- <body name="w3" pos="0.125 0.117 0" quat="0.499998 0.5 -0.5 0.500002"> -->
            <body name="w3" pos="0.0875 0.117 0.095" quat="0.683 0.183 -0.183 -0.683">
                <inertial pos="0 0.01 0" quat="0.707107 0 0 0.707107" mass="0.15708"
                    diaginertia="0.00019635 0.00010341 0.00010341" />
                <joint name="w3" pos="0 0 0" axis="0 -1 0" damping="0.1" />
                <geom type="mesh" mesh="w3" friction="0.2 0.005 0.01" condim="6" />
            </body>
            <!-- <body name="w4" pos="0 0.117 0.125" quat="0.499998 0.5 -0.5 0.500002"> -->
            <!-- <inertial pos="-0.01 0 0" mass="0.15708" diaginertia="0.00019635 0.00010341
            0.00010341"
      /> -->
            <!-- <joint name="w4" pos="0 0 0" axis="1 0 0" damping="0.1" /> -->
            <!-- w4: Yellow -->
            <!-- <geom type="mesh" mesh="w4" friction="0.2 0.005 0.01" condim="6" /> -->
            <!-- <geom type="mesh" rgba="1 1 0 1" mesh="w4" friction="0.0 0.0 0.0" condim="1" /> -->
            <!-- </body> -->
        </body>
    </worldbody>

    <actuator>
        <position name="a1_motor" joint="a1" kp="5" kv="1" ctrlrange="-3.14 3.14" />
        <position name="a2_motor" joint="a2" kp="10" kv="5" ctrlrange="0.7 1.5" />
        <position name="h_motor" joint="h" kp="5" kv="1" ctrlrange="-3.14 3.14" />

        <velocity name="bd_motor" joint="base_link_freejoint" kv="5" ctrlrange="-10 10"
            gear="1.375 0 0 0 0 0" />
        <velocity name="bf_motor" joint="base_link_freejoint" kv="5" ctrlrange="-10 10"
            gear="0 1.375 0 0 0 0" />

        <velocity name="br_motor" joint="base_link_freejoint" kv="1" ctrlrange="-2 2"
            gear="0 0 0 0 1 0" />


        <!-- <motor name="w1_motor" joint="w1" gear="5" ctrllimited="true" ctrlrange="-1 1" />
    <motor name="w2_motor" joint="w2" gear="5" ctrllimited="true" ctrlrange="-1 1" />
    <motor name="w3_motor" joint="w3" gear="5" ctrllimited="true" ctrlrange="-1 1" />
    <motor name="w4_motor" joint="w4" gear="5" ctrllimited="true" ctrlrange="-1 1" /> -->

        <!-- Original -->
        <!-- <position name="a1_motor" joint="a1" kp="5" kv="1" ctrlrange="-3.14 3.14"/>
    <position name="a2_motor" joint="a2" kp="2" kv="1" ctrlrange="-3.14 3.14"/>
    <position name="h_motor" joint="h" kp="5" kv="1" ctrlrange="-3.14 3.14"/> -->
        <!-- <position name="w1_motor" joint="w1" kp="5" kv="1" ctrlrange="-3.14 3.14"/>
    <position name="w2_motor" joint="w2" kp="5" kv="1" ctrlrange="-3.14 3.14"/>
    <position name="w3_motor" joint="w3" kp="5" kv="1" ctrlrange="-3.14 3.14"/>
    <position name="w4_motor" joint="w4" kp="5" kv="1" ctrlrange="-3.14 3.14"/> -->
    </actuator>
</mujoco>