<mujoco model="bb8_car_thisone">
  <compiler angle="radian"/>

  <asset>
    <mesh name="base_link" content_type="model/stl" file="base_link.STL"/>
    <mesh name="lazy_susan" content_type="model/stl" file="lazy_susan.STL"/>
    <mesh name="arm" content_type="model/stl" file="arm.STL"/>
    <mesh name="head" content_type="model/stl" file="head.STL"/>
    <mesh name="w1" content_type="model/stl" file="w1.STL"/>
    <mesh name="w2" content_type="model/stl" file="w2.STL"/>
    <mesh name="w3" content_type="model/stl" file="w3.STL"/>
    <mesh name="w4" content_type="model/stl" file="w4.STL"/>
  </asset>

  <worldbody>
    <geom type="mesh" rgba="0.79216 0.81961 0.93333 1" mesh="base_link"/>
    <body name="lazy_susan">
      <inertial pos="0 0 -0.0081795" quat="0.5 0.5 -0.5 0.5" mass="0.65546" diaginertia="0.0031434 0.0015976 0.0015976"/>
      <joint name="lazy_susan" pos="0 0 0" axis="0 0 -1"/>
      <geom type="mesh" rgba="0.79216 0.81961 0.93333 1" mesh="lazy_susan"/>
      <body name="arm" pos="0 -0.01 0.06" quat="1.34924e-11 -3.67321e-06 1 -3.67321e-06">
        <inertial pos="1.2577e-10 0.01 -0.12424" quat="0.711902 0 0 0.702278" mass="0.072732" diaginertia="0.00032679 0.00032678 3.6454e-06"/>
        <joint name="arm" pos="0 0 0" axis="0 -1 0"/>
        <geom type="mesh" rgba="0.79216 0.81961 0.93333 1" mesh="arm"/>
        <body name="head" pos="0 0.01 -0.24" quat="-1.66326e-07 0.0452808 -0.998974 3.66944e-06">
          <inertial pos="0 0 0.0553125" quat="0.5 0.5 -0.5 0.5" mass="6.72101" diaginertia="0.0584896 0.0379269 0.0379269"/>
          <joint name="head" pos="0 0 0" axis="0 0 -1"/>
          <geom type="mesh" rgba="0.792157 0.819608 0.933333 1" mesh="head"/>
        </body>
      </body>
    </body>
    <body name="w1" pos="0 -0.2 -0.137" quat="1.34924e-11 -3.67321e-06 1 -3.67321e-06">
      <inertial pos="0 0.01 0" quat="0.707107 0 0 0.707107" mass="0.15708" diaginertia="0.00019635 0.00010341 0.00010341"/>
      <joint name="w1" pos="0 0 0" axis="0 1 0"/>
      <geom type="mesh" rgba="0.79216 0.81961 0.93333 1" mesh="w1"/>
    </body>
    <body name="w2" pos="-0.2 0 -0.137" quat="-2.59734e-06 -0.707105 -0.707108 -2.59735e-06">
      <inertial pos="0 0.01 0" quat="0.707107 0 0 0.707107" mass="0.15708" diaginertia="0.00019635 0.00010341 0.00010341"/>
      <joint name="w2" pos="0 0 0" axis="0 1 0"/>
      <geom type="mesh" rgba="0.79216 0.81961 0.93333 1" mesh="w2"/>
    </body>
    <body name="w3" pos="0.2 0 -0.137" quat="-2.59734e-06 0.707105 -0.707108 2.59735e-06">
      <inertial pos="0 0.01 0" quat="0.707107 0 0 0.707107" mass="0.15708" diaginertia="0.00019635 0.00010341 0.00010341"/>
      <joint name="w3" pos="0 0 0" axis="0 1 0"/>
      <geom type="mesh" rgba="0.79216 0.81961 0.93333 1" mesh="w3"/>
    </body>
    <body name="w4" pos="0 0.2 -0.137" quat="-3.67321e-06 -1 0 0">
      <inertial pos="0 0.01 0" quat="0.707107 0 0 0.707107" mass="0.15708" diaginertia="0.00019635 0.00010341 0.00010341"/>
      <joint name="w4" pos="0 0 0" axis="0 1 0"/>
      <geom type="mesh" rgba="0.79216 0.81961 0.93333 1" mesh="w4"/>
    </body>
  </worldbody>
</mujoco>
